# Chapter47
## 📌문제1
### 다음 코드의 실행 결과를 서술하시오.
```js
const func = (n, f) => {
  if(typeof f !== 'function') new Error('f must be function');
  f(n);
}

try {
  func(1, 2);
}catch(e){
   console.log(e);
}
```
### 정답 및 해설
```
TypeError: f is not a function
error을 throw 하지 않아서 try catch 문에서 에러 처리가 되지 않는다
```

<br>

## 📌문제2

### 다음 코드의 실행 결과를 예상해보고, 의도에 맞게 고치세요.

```js
const practice = (n, f) => {
  if (typeof f !== "function") {
    new TypeError("f must be a function");
  }
};

try {
  practice(2, 1);
  new Error("something wrong");
} catch (error) {
  console.log(error);
}
```

### 정답 및 해설
```
890p
Error 생성자 함수로 에러 객체를 생성한다고 에러가 발생하는 것은 아닙니다.
즉, 에러 객체 생성과 에러 발생은 의미가 다릅니다.
에러를 발생시키려면 try 코드 블록에서 throw 문으로 에러 객체를 던져야 합니다.
```
```js
const practice = (n, f) => {
  if (typeof f !== "function") {
    throw new TypeError("f must be a function");
  }
};

try {
  practice(2, 1);
  new Error("something wrong");
} catch (error) {
  console.log(error);
}
```

<br>

## 📌문제3
### 다음 코드의 `(1)에서 this`가 무엇일지 작성하고, `(2)전체 실행 출력 결과`를 작성하시오.
```js
const obj = {
  name: 'i am object'
};

async function test2() {
  try {
    throw 123;
  } catch (error) {
    // (1) this
    console.log('test2-catch');
    throw new Error('test2-catch');
  }
}

function test1() {
  try {
    test2.bind(obj)();
    console.log('test1-try');
  } catch (error) {
    console.log('test1-catch');
    throw new Error('test1-catch');
  }
}

try {
  test1()
} catch (error) {
  console.log(error);
}
```
### 정답 및 해설
```
(1) : obj {name: 'i am object'}
try 영역이든 catch 영역이든 동일한 test2 실행컨텍스트에서 실행된다.

(2) : 
test2-catch
test1-try
Uncaught (in promise) Error: test2-catch

test2에서는 프로미스를 반환하므로
test1에서 test2함수 실행완료 때까지 에러라고 감지하지 않습니다.
따라서 async가 붙은 test2의 catch에서 throw한 에러를 받으려면
test1에서 아래와 같이 catch메서드를 작성해야합니다.
```
```js
test2.bind(obj)().catch((res) => console.log(res));
```

<br>
